2019-11-27 23:38:54,813 INFO: application started [in ./init.py:48]
2019-11-27 23:38:54,815 INFO: ['william.bergamin.coen@gmail.com', 'roumeliotisconstantina@gmail.com'] [in ./init.py:49]
2019-11-27 23:39:20,662 ERROR: Exception on /api/v1/user [POST] [in /usr/local/lib/python3.7/site-packages/flask/app.py:1761]
Traceback (most recent call last):
  File "/usr/local/lib/python3.7/site-packages/flask/app.py", line 2292, in wsgi_app
    response = self.full_dispatch_request()
  File "/usr/local/lib/python3.7/site-packages/flask/app.py", line 1815, in full_dispatch_request
    rv = self.handle_user_exception(e)
  File "/usr/local/lib/python3.7/site-packages/flask_cors/extension.py", line 161, in wrapped_function
    return cors_after_request(app.make_response(f(*args, **kwargs)))
  File "/usr/local/lib/python3.7/site-packages/flask/app.py", line 1718, in handle_user_exception
    reraise(exc_type, exc_value, tb)
  File "/usr/local/lib/python3.7/site-packages/flask/_compat.py", line 35, in reraise
    raise value
  File "/usr/local/lib/python3.7/site-packages/flask/app.py", line 1813, in full_dispatch_request
    rv = self.dispatch_request()
  File "/usr/local/lib/python3.7/site-packages/flask/app.py", line 1799, in dispatch_request
    return self.view_functions[rule.endpoint](**req.view_args)
  File "./app.py", line 85, in post_user
    email=data['email'],
KeyError: 'email'
2019-11-27 23:52:09,618 INFO: application started [in ./init.py:48]
2019-11-27 23:52:09,620 INFO: ['william.bergamin.coen@gmail.com', 'roumeliotisconstantina@gmail.com'] [in ./init.py:49]
2019-11-27 23:52:24,737 ERROR: Exception on /api/v1/user [POST] [in /usr/local/lib/python3.7/site-packages/flask/app.py:1761]
Traceback (most recent call last):
  File "/usr/local/lib/python3.7/site-packages/flask/app.py", line 2292, in wsgi_app
    response = self.full_dispatch_request()
  File "/usr/local/lib/python3.7/site-packages/flask/app.py", line 1815, in full_dispatch_request
    rv = self.handle_user_exception(e)
  File "/usr/local/lib/python3.7/site-packages/flask_cors/extension.py", line 161, in wrapped_function
    return cors_after_request(app.make_response(f(*args, **kwargs)))
  File "/usr/local/lib/python3.7/site-packages/flask/app.py", line 1718, in handle_user_exception
    reraise(exc_type, exc_value, tb)
  File "/usr/local/lib/python3.7/site-packages/flask/_compat.py", line 35, in reraise
    raise value
  File "/usr/local/lib/python3.7/site-packages/flask/app.py", line 1813, in full_dispatch_request
    rv = self.dispatch_request()
  File "/usr/local/lib/python3.7/site-packages/flask/app.py", line 1799, in dispatch_request
    return self.view_functions[rule.endpoint](**req.view_args)
  File "./app.py", line 85, in post_user
    email=data['email'],
KeyError: 'email'
2019-11-27 23:58:32,973 INFO: application started [in ./init.py:48]
2019-11-27 23:58:32,976 INFO: ['william.bergamin.coen@gmail.com', 'roumeliotisconstantina@gmail.com'] [in ./init.py:49]
2019-11-27 23:59:05,886 ERROR: Exception on /api/v1/user [POST] [in /usr/local/lib/python3.7/site-packages/flask/app.py:1761]
Traceback (most recent call last):
  File "/usr/local/lib/python3.7/site-packages/flask/app.py", line 2292, in wsgi_app
    response = self.full_dispatch_request()
  File "/usr/local/lib/python3.7/site-packages/flask/app.py", line 1815, in full_dispatch_request
    rv = self.handle_user_exception(e)
  File "/usr/local/lib/python3.7/site-packages/flask_cors/extension.py", line 161, in wrapped_function
    return cors_after_request(app.make_response(f(*args, **kwargs)))
  File "/usr/local/lib/python3.7/site-packages/flask/app.py", line 1718, in handle_user_exception
    reraise(exc_type, exc_value, tb)
  File "/usr/local/lib/python3.7/site-packages/flask/_compat.py", line 35, in reraise
    raise value
  File "/usr/local/lib/python3.7/site-packages/flask/app.py", line 1813, in full_dispatch_request
    rv = self.dispatch_request()
  File "/usr/local/lib/python3.7/site-packages/flask/app.py", line 1799, in dispatch_request
    return self.view_functions[rule.endpoint](**req.view_args)
  File "./app.py", line 85, in post_user
    email=data['email'],
KeyError: 'email'
2019-11-28 00:04:08,425 INFO: application started [in ./init.py:48]
2019-11-28 00:04:08,427 INFO: ['william.bergamin.coen@gmail.com'] [in ./init.py:49]
2019-11-28 00:04:14,873 ERROR: Exception on /api/v1/user [POST] [in /usr/local/lib/python3.7/site-packages/flask/app.py:1761]
Traceback (most recent call last):
  File "/usr/local/lib/python3.7/site-packages/flask/app.py", line 2292, in wsgi_app
    response = self.full_dispatch_request()
  File "/usr/local/lib/python3.7/site-packages/flask/app.py", line 1815, in full_dispatch_request
    rv = self.handle_user_exception(e)
  File "/usr/local/lib/python3.7/site-packages/flask_cors/extension.py", line 161, in wrapped_function
    return cors_after_request(app.make_response(f(*args, **kwargs)))
  File "/usr/local/lib/python3.7/site-packages/flask/app.py", line 1718, in handle_user_exception
    reraise(exc_type, exc_value, tb)
  File "/usr/local/lib/python3.7/site-packages/flask/_compat.py", line 35, in reraise
    raise value
  File "/usr/local/lib/python3.7/site-packages/flask/app.py", line 1813, in full_dispatch_request
    rv = self.dispatch_request()
  File "/usr/local/lib/python3.7/site-packages/flask/app.py", line 1799, in dispatch_request
    return self.view_functions[rule.endpoint](**req.view_args)
  File "./app.py", line 85, in post_user
    email=data['email'],
KeyError: 'email'
2019-11-28 00:15:53,188 INFO: application started [in ./init.py:48]
2019-11-28 00:15:53,190 INFO: ['william.bergamin.coen@gmail.com'] [in ./init.py:49]
2019-11-28 00:16:02,821 ERROR: Exception on /api/v1/user [POST] [in /usr/local/lib/python3.7/site-packages/flask/app.py:1761]
Traceback (most recent call last):
  File "/usr/local/lib/python3.7/site-packages/flask/app.py", line 2292, in wsgi_app
    response = self.full_dispatch_request()
  File "/usr/local/lib/python3.7/site-packages/flask/app.py", line 1815, in full_dispatch_request
    rv = self.handle_user_exception(e)
  File "/usr/local/lib/python3.7/site-packages/flask_cors/extension.py", line 161, in wrapped_function
    return cors_after_request(app.make_response(f(*args, **kwargs)))
  File "/usr/local/lib/python3.7/site-packages/flask/app.py", line 1718, in handle_user_exception
    reraise(exc_type, exc_value, tb)
  File "/usr/local/lib/python3.7/site-packages/flask/_compat.py", line 35, in reraise
    raise value
  File "/usr/local/lib/python3.7/site-packages/flask/app.py", line 1813, in full_dispatch_request
    rv = self.dispatch_request()
  File "/usr/local/lib/python3.7/site-packages/flask/app.py", line 1799, in dispatch_request
    return self.view_functions[rule.endpoint](**req.view_args)
  File "./app.py", line 85, in post_user
    email=data['email'],
KeyError: 'email'
2019-11-28 00:21:09,420 INFO: application started [in ./init.py:48]
2019-11-28 00:21:09,422 INFO: ['william.bergamin.coen@gmail.com'] [in ./init.py:49]
2019-11-28 00:21:32,482 ERROR: Exception on /api/v1/user [POST] [in /usr/local/lib/python3.7/site-packages/flask/app.py:1761]
Traceback (most recent call last):
  File "/usr/local/lib/python3.7/site-packages/flask/app.py", line 2292, in wsgi_app
    response = self.full_dispatch_request()
  File "/usr/local/lib/python3.7/site-packages/flask/app.py", line 1815, in full_dispatch_request
    rv = self.handle_user_exception(e)
  File "/usr/local/lib/python3.7/site-packages/flask_cors/extension.py", line 161, in wrapped_function
    return cors_after_request(app.make_response(f(*args, **kwargs)))
  File "/usr/local/lib/python3.7/site-packages/flask/app.py", line 1718, in handle_user_exception
    reraise(exc_type, exc_value, tb)
  File "/usr/local/lib/python3.7/site-packages/flask/_compat.py", line 35, in reraise
    raise value
  File "/usr/local/lib/python3.7/site-packages/flask/app.py", line 1813, in full_dispatch_request
    rv = self.dispatch_request()
  File "/usr/local/lib/python3.7/site-packages/flask/app.py", line 1799, in dispatch_request
    return self.view_functions[rule.endpoint](**req.view_args)
  File "./app.py", line 85, in post_user
    email=data['email'],
KeyError: 'email'
2019-11-28 00:22:58,092 INFO: application started [in ./init.py:48]
2019-11-28 00:22:58,094 INFO: ['william.bergamin.coen@gmail.com'] [in ./init.py:49]
2019-11-28 00:23:08,307 ERROR: Exception on /api/v1/user [POST] [in /usr/local/lib/python3.7/site-packages/flask/app.py:1761]
Traceback (most recent call last):
  File "/usr/local/lib/python3.7/site-packages/flask/app.py", line 2292, in wsgi_app
    response = self.full_dispatch_request()
  File "/usr/local/lib/python3.7/site-packages/flask/app.py", line 1815, in full_dispatch_request
    rv = self.handle_user_exception(e)
  File "/usr/local/lib/python3.7/site-packages/flask_cors/extension.py", line 161, in wrapped_function
    return cors_after_request(app.make_response(f(*args, **kwargs)))
  File "/usr/local/lib/python3.7/site-packages/flask/app.py", line 1718, in handle_user_exception
    reraise(exc_type, exc_value, tb)
  File "/usr/local/lib/python3.7/site-packages/flask/_compat.py", line 35, in reraise
    raise value
  File "/usr/local/lib/python3.7/site-packages/flask/app.py", line 1813, in full_dispatch_request
    rv = self.dispatch_request()
  File "/usr/local/lib/python3.7/site-packages/flask/app.py", line 1799, in dispatch_request
    return self.view_functions[rule.endpoint](**req.view_args)
  File "./app.py", line 85, in post_user
    email=data['email'],
KeyError: 'email'
2019-11-28 00:31:22,639 INFO: application started [in ./init.py:48]
2019-11-28 00:31:22,641 INFO: ['william.bergamin.coen@gmail.com'] [in ./init.py:49]
2019-11-28 00:31:37,977 ERROR: Exception on /api/v1/user [POST] [in /usr/local/lib/python3.7/site-packages/flask/app.py:1761]
Traceback (most recent call last):
  File "/usr/local/lib/python3.7/site-packages/flask/app.py", line 2292, in wsgi_app
    response = self.full_dispatch_request()
  File "/usr/local/lib/python3.7/site-packages/flask/app.py", line 1815, in full_dispatch_request
    rv = self.handle_user_exception(e)
  File "/usr/local/lib/python3.7/site-packages/flask_cors/extension.py", line 161, in wrapped_function
    return cors_after_request(app.make_response(f(*args, **kwargs)))
  File "/usr/local/lib/python3.7/site-packages/flask/app.py", line 1718, in handle_user_exception
    reraise(exc_type, exc_value, tb)
  File "/usr/local/lib/python3.7/site-packages/flask/_compat.py", line 35, in reraise
    raise value
  File "/usr/local/lib/python3.7/site-packages/flask/app.py", line 1813, in full_dispatch_request
    rv = self.dispatch_request()
  File "/usr/local/lib/python3.7/site-packages/flask/app.py", line 1799, in dispatch_request
    return self.view_functions[rule.endpoint](**req.view_args)
  File "./app.py", line 85, in post_user
    email=data['email'],
KeyError: 'email'
2019-11-28 00:33:22,753 INFO: application started [in ./init.py:48]
2019-11-28 00:33:22,759 INFO: ['william.bergamin.coen@gmail.com'] [in ./init.py:49]
2019-11-28 00:33:38,104 ERROR: Exception on /api/v1/user [POST] [in /usr/local/lib/python3.7/site-packages/flask/app.py:1761]
Traceback (most recent call last):
  File "/usr/local/lib/python3.7/site-packages/flask/app.py", line 2292, in wsgi_app
    response = self.full_dispatch_request()
  File "/usr/local/lib/python3.7/site-packages/flask/app.py", line 1815, in full_dispatch_request
    rv = self.handle_user_exception(e)
  File "/usr/local/lib/python3.7/site-packages/flask_cors/extension.py", line 161, in wrapped_function
    return cors_after_request(app.make_response(f(*args, **kwargs)))
  File "/usr/local/lib/python3.7/site-packages/flask/app.py", line 1718, in handle_user_exception
    reraise(exc_type, exc_value, tb)
  File "/usr/local/lib/python3.7/site-packages/flask/_compat.py", line 35, in reraise
    raise value
  File "/usr/local/lib/python3.7/site-packages/flask/app.py", line 1813, in full_dispatch_request
    rv = self.dispatch_request()
  File "/usr/local/lib/python3.7/site-packages/flask/app.py", line 1799, in dispatch_request
    return self.view_functions[rule.endpoint](**req.view_args)
  File "./app.py", line 85, in post_user
    email=data['email'],
KeyError: 'email'
2019-11-28 00:37:04,729 INFO: application started [in ./init.py:48]
2019-11-28 00:37:04,732 INFO: ['william.bergamin.coen@gmail.com'] [in ./init.py:49]
2019-11-28 00:37:11,567 ERROR: Exception on /api/v1/user [POST] [in /usr/local/lib/python3.7/site-packages/flask/app.py:1761]
Traceback (most recent call last):
  File "/usr/local/lib/python3.7/site-packages/flask/app.py", line 2292, in wsgi_app
    response = self.full_dispatch_request()
  File "/usr/local/lib/python3.7/site-packages/flask/app.py", line 1815, in full_dispatch_request
    rv = self.handle_user_exception(e)
  File "/usr/local/lib/python3.7/site-packages/flask_cors/extension.py", line 161, in wrapped_function
    return cors_after_request(app.make_response(f(*args, **kwargs)))
  File "/usr/local/lib/python3.7/site-packages/flask/app.py", line 1718, in handle_user_exception
    reraise(exc_type, exc_value, tb)
  File "/usr/local/lib/python3.7/site-packages/flask/_compat.py", line 35, in reraise
    raise value
  File "/usr/local/lib/python3.7/site-packages/flask/app.py", line 1813, in full_dispatch_request
    rv = self.dispatch_request()
  File "/usr/local/lib/python3.7/site-packages/flask/app.py", line 1799, in dispatch_request
    return self.view_functions[rule.endpoint](**req.view_args)
  File "./app.py", line 85, in post_user
    email=data['email'],
KeyError: 'email'
2019-11-28 00:42:51,492 INFO: application started [in ./init.py:48]
2019-11-28 00:42:51,494 INFO: ['william.bergamin.coen@gmail.com'] [in ./init.py:49]
2019-11-28 00:42:56,689 ERROR: Exception on /api/v1/user [POST] [in /usr/local/lib/python3.7/site-packages/flask/app.py:1761]
Traceback (most recent call last):
  File "/usr/local/lib/python3.7/site-packages/flask/app.py", line 2292, in wsgi_app
    response = self.full_dispatch_request()
  File "/usr/local/lib/python3.7/site-packages/flask/app.py", line 1815, in full_dispatch_request
    rv = self.handle_user_exception(e)
  File "/usr/local/lib/python3.7/site-packages/flask_cors/extension.py", line 161, in wrapped_function
    return cors_after_request(app.make_response(f(*args, **kwargs)))
  File "/usr/local/lib/python3.7/site-packages/flask/app.py", line 1718, in handle_user_exception
    reraise(exc_type, exc_value, tb)
  File "/usr/local/lib/python3.7/site-packages/flask/_compat.py", line 35, in reraise
    raise value
  File "/usr/local/lib/python3.7/site-packages/flask/app.py", line 1813, in full_dispatch_request
    rv = self.dispatch_request()
  File "/usr/local/lib/python3.7/site-packages/flask/app.py", line 1799, in dispatch_request
    return self.view_functions[rule.endpoint](**req.view_args)
  File "./app.py", line 85, in post_user
    email=data['email'],
KeyError: 'email'
2019-11-28 00:45:34,312 INFO: Email already used for existing user [in ./utils.py:16]
